Workbook

Sheet Catalogue
A1: rowType | B1: extensionId | C1: extensionName | D1: extensionCoverImageRef | E1: cardId | F1: name | G1: rarityLabel | H1: cardRarityMultiplier | I1: imageRef | J1: variantProfileId | K1: commonName | L1: primaryCatalogName | M1: catalogNumber | N1: objectFamily | O1: objectTypeLabel | P1: constellation | Q1: mainSeason | R1: rightAscensionHours | S1: rightAscensionMinutes | T1: rightAscensionSeconds | U1: rightAscensionLabel | V1: declinationSign | W1: declinationDegrees | X1: declinationArcMinutes | Y1: declinationArcSeconds | Z1: declinationLabel | AA1: coordinatesLabel | AB1: shortDescription | AC1: detailType | AD1: distanceLightYears | AE1: distanceLabel | AF1: realSizeLightYears | AG1: realSizeLabel | AH1: visualFullMoonWidth | AI1: visualFullMoonHeight | AJ1: angularWidthDegrees | AK1: angularWidthArcMinutes | AL1: angularWidthArcSeconds | AM1: angularWidthLabel | AN1: angularHeightDegrees | AO1: angularHeightArcMinutes | AP1: angularHeightArcSeconds | AQ1: angularHeightLabel | AR1: visualSizeLabel | AS1: absoluteMagnitudeValue | AT1: absoluteMagnitudeLabel | AU1: visualMagnitudeValue | AV1: visualMagnitudeLabel
A2: extension | B2: astronomes-en-herbe | C2: Astronomes en herbe | D2: cover_astronomes_en_herbe
A3: card | B3: astronomes-en-herbe | E3: aeh-albireo | F3: Albiréo | G3: Common | H3: 1 | I3: albireo | J3: observation-default | K3: Albiréo | L3: Bayer | M3: Beta Cygni | N3: star | O3: Etoile double coloree | P3: Cygne | Q3: Ete | R3: 19 | S3: 30 | T3: 43 | U3: AD 19h 30m 43,0s | V3: + | W3: 27 | X3: 58 | Y3: 0 | Z3: +27° 58′ 00″ | AA3: AD 19h 30m 43,0s ; Dec +27° 58′ 00″ | AB3: Belle étoile double bleu et jaune, formant la tête de la constellation du Cygne. | AC3: star | AD3: 420 | AE3: 420 annees-lumiere | AF3: 0.005 | AG3: 0,005 annee-lumiere | AS3: -2.3 | AT3: -2.3 | AU3: 3.08 | AV3: 3.08
A4: card | B4: astronomes-en-herbe | E4: aeh-algol | F4: Algol | G4: Uncommon | H4: 1 | I4: algol | J4: observation-default | K4: Algol | L4: Bayer | M4: Beta Persei | N4: star | O4: Etoile variable eclipsante | P4: Persee | Q4: Automne | R4: 3 | S4: 8 | T4: 10 | U4: AD 03h 08m 10,0s | V4: + | W4: 40 | X4: 57 | Y4: 20 | Z4: +40° 57′ 20″ | AA4: AD 03h 08m 10,0s ; Dec +40° 57′ 20″ | AB4: Étoile variable célèbre car sa période est de 3 jours. Ses changements de luminosités sont donc faciles à suivre au fil des nuits. | AC4: star | AD4: 93 | AE4: 93 annees-lumiere | AF4: 0.0003 | AG4: 0,0003 annee-lumiere | AS4: -0.2 | AT4: -0.2 | AU4: 2.12 | AV4: 2.12
A5: card | B5: astronomes-en-herbe | E5: aeh-almach | F5: Almach | G5: Uncommon | H5: 1 | I5: almach | J5: observation-default | K5: Almach | L5: Bayer | M5: Gamma Andromedae | N5: star | O5: Etoile double coloree | P5: Andromede | Q5: Automne | R5: 2 | S5: 3 | T5: 54 | U5: AD 02h 03m 54,0s | V5: + | W5: 42 | X5: 19 | Y5: 47 | Z5: +42° 19′ 47″ | AA5: AD 02h 03m 54,0s ; Dec +42° 19′ 47″ | AB5: Étoile double colorée très connue car la deuxième étoile du système est également une étoile double ! | AC5: star | AD5: 350 | AE5: 350 annees-lumiere | AF5: 1.18e-05 | AG5: 0,0000118 annee-lumiere | AS5: -0.3 | AT5: -0.3 | AU5: 2.1 | AV5: 2.1
A6: card | B6: astronomes-en-herbe | E6: aeh-altair | F6: Altaïr | G6: Common | H6: 1 | I6: altair | J6: observation-default | K6: Altaïr | L6: Bayer | M6: Alpha Aquilae | N6: star | O6: Etoile blanche | P6: Aigle | Q6: Ete | R6: 19 | S6: 50 | T6: 47 | U6: AD 19h 50m 47,0s | V6: + | W6: 8 | X6: 52 | Y6: 6 | Z6: +08° 52′ 06″ | AA6: AD 19h 50m 47,0s ; Dec +08° 52′ 06″ | AB6: Étoile brillante du Triangle d'été, au centre de la tête de « l’Aigle Volant ». | AC6: star | AD6: 16.7 | AE6: 16,7 annees-lumiere | AF6: 2.65e-07 | AG6: 0,000000265 annee-lumiere | AS6: 2.2 | AT6: 2.2 | AU6: 0.76 | AV6: 0.76
A7: card | B7: astronomes-en-herbe | E7: aeh-andromede-constellation | F7: Andromède | G7: Common | H7: 1 | I7: andromeda_constellation | J7: observation-default | K7: Andromède | L7: IAU | M7: AND | N7: constellation | O7: Constellation | P7: Andromede | Q7: Automne | R7: 1 | S7: 0 | T7: 0 | U7: AD 01h 00m 00,0s | V7: + | W7: 38 | X7: 0 | Y7: 0 | Z7: +38° 00′ 00″ | AA7: AD 01h 00m 00,0s ; Dec +38° 00′ 00″ | AB7: Constellation formant les pates arrières de Pégase, connue pour habriter la galaxie d'Andromède. | AC7: constellation | AH7: 11 | AI7: 5 | AJ7: 5 | AK7: 30 | AL7: 0 | AM7: 5°30′00″ | AN7: 2 | AO7: 30 | AP7: 0 | AQ7: 2°30′00″ | AR7: 11,00 × 5,00 (5°30′00″ × 2°30′00″)
A8: card | B8: astronomes-en-herbe | E8: aeh-arcturus | F8: Arcturus | G8: Common | H8: 1 | I8: arcturus | J8: observation-default | K8: Arcturus | L8: Bayer | M8: Alpha Bootis | N8: star | O8: Geante orange | P8: Bouvier | Q8: Printemps | R8: 14 | S8: 15 | T8: 39.7 | U8: AD 14h 15m 39,7s | V8: + | W8: 19 | X8: 10 | Y8: 57 | Z8: +19° 10′ 57″ | AA8: AD 14h 15m 39,7s ; Dec +19° 10′ 57″ | AB8: Géante rouge qui proviendrait d'une petite galaxie qui serait entrée en collision et aurait fusionné avec la Voie lactée il y a 5 à 8 milliards d'années. | AC8: star | AD8: 36.7 | AE8: 36,7 annees-lumiere | AF8: 3.73e-06 | AG8: 0,00000373 annee-lumiere | AS8: -0.3 | AT8: -0.3 | AU8: -0.05 | AV8: -0.05
A9: card | B9: astronomes-en-herbe | E9: aeh-aurora-borealis | F9: Aurore boréale | G9: Epic | H9: 1 | I9: aurora_borealis | J9: observation-default | K9: Aurore boréale | L9: Geophysique | M9: AUR-N | N9: sky_event | O9: Phenomenes lumineux polaires | P9: Circumpolaire | Q9: Automne-Hiver | R9: 0 | S9: 0 | T9: 0 | U9: AD 00h 00m 00,0s | V9: + | W9: 70 | X9: 0 | Y9: 0 | Z9: +70° 00′ 00″ | AA9: AD 00h 00m 00,0s ; Dec +70° 00′ 00″ | AB9: Voiles lumineux polaires spectaculaires, célèbres pour leurs couleurs mouvantes. | AC9: sky_event | AH9: 120 | AI9: 60 | AJ9: 60 | AK9: 0 | AL9: 0 | AM9: 60°00′00″ | AN9: 30 | AO9: 0 | AP9: 0 | AQ9: 30°00′00″ | AR9: 120,00 × 60,00 (60°00′00″ × 30°00′00″)
A10: card | B10: astronomes-en-herbe | E10: aeh-betelgeuse | F10: Bételgeuse | G10: Common | H10: 1 | I10: betelgeuse | J10: observation-default | K10: Bételgeuse | L10: Bayer | M10: Alpha Orionis | N10: star | O10: Supergeante rouge | P10: Orion | Q10: Hiver | R10: 5 | S10: 55 | T10: 10.3 | U10: AD 05h 55m 10,3s | V10: + | W10: 7 | X10: 24 | Y10: 25 | Z10: +07° 24′ 25″ | AA10: AD 05h 55m 10,3s ; Dec +07° 24′ 25″ | AB10: Supergéante rouge célèbre par sa luminosité et sa couleur orange, facile à remarquer à l'œil nu dans la constellation d'Orion. | AC10: star | AD10: 548 | AE10: 548 annees-lumiere | AF10: 0.00011 | AG10: 0,00011 annee-lumiere | AS10: -5.85 | AT10: -5.85 | AU10: 0.42 | AV10: 0.42
A11: card | B11: astronomes-en-herbe | E11: aeh-capella | F11: Capella | G11: Common | H11: 1 | I11: capella | J11: observation-default | K11: Capella | L11: Bayer | M11: Alpha Aurigae | N11: star | O11: Etoile multiple | P11: Cocher | Q11: Hiver | R11: 5 | S11: 16 | T11: 41 | U11: AD 05h 16m 41,0s | V11: + | W11: 45 | X11: 59 | Y11: 53 | Z11: +45° 59′ 53″ | AA11: AD 05h 16m 41,0s ; Dec +45° 59′ 53″ | AB11: De la constellation du Cocher, c'est la quatrième étoile la plus brillante du ciel du Nord après Sirius, Arcturus et Véga. | AC11: star | AD11: 42.9 | AE11: 42,9 annees-lumiere | AF11: 1.76e-06 | AG11: 0,00000176 annee-lumiere | AS11: 0.3 | AT11: 0.3 | AU11: 0.08 | AV11: 0.08
A12: card | B12: astronomes-en-herbe | E12: aeh-cassiopeia | F12: Cassiopée | G12: Common | H12: 1 | I12: cassiopeia_constellation | J12: observation-default | K12: Cassiopée | L12: IAU | M12: CAS | N12: constellation | O12: Constellation | P12: Cassiopee | Q12: Automne | R12: 1 | S12: 0 | T12: 0 | U12: AD 01h 00m 00,0s | V12: + | W12: 60 | X12: 0 | Y12: 0 | Z12: +60° 00′ 00″ | AA12: AD 01h 00m 00,0s ; Dec +60° 00′ 00″ | AB12: Constellation en forme de W, elle fait partie des "circumpolaires" : les constellations qui ne se couchent jamais. | AC12: constellation | AH12: 10 | AI12: 7 | AJ12: 5 | AK12: 0 | AL12: 0 | AM12: 5°00′00″ | AN12: 3 | AO12: 30 | AP12: 0 | AQ12: 3°30′00″ | AR12: 10,00 × 7,00 (5°00′00″ × 3°30′00″)
A13: card | B13: astronomes-en-herbe | E13: aeh-coathanger | F13: Amas du Cintre | G13: Uncommon | H13: 1 | I13: coathanger | J13: observation-default | K13: Amas du Cintre | L13: Collinder | M13: Cr 399 | N13: deep_sky | O13: Asterisme | P13: Petit Renard | Q13: Ete | R13: 19 | S13: 26 | T13: 0 | U13: AD 19h 26m 00,0s | V13: + | W13: 20 | X13: 11 | Y13: 0 | Z13: +20° 11′ 00″ | AA13: AD 19h 26m 00,0s ; Dec +20° 11′ 00″ | AB13: Astérisme amusant en forme de cintre, facile à observer aux jumelles sous un bon ciel. | AC13: deep_sky | AD13: 420 | AE13: 420 annees-lumiere | AF13: 30 | AG13: 30 annees-lumiere | AH13: 2.5 | AI13: 1.3 | AJ13: 1 | AK13: 16 | AL13: 0 | AM13: 1°16′00″ | AN13: 0 | AO13: 40 | AP13: 0 | AQ13: 0°40′00″ | AR13: 2,50 × 1,30 (1°16′00″ × 0°40′00″) | AS13: -1 | AT13: -1 | AU13: 3.6 | AV13: 3.6
A14: card | B14: astronomes-en-herbe | E14: aeh-comet-neowise | F14: Comète C/2020 F3 NEOWISE | G14: Epic | H14: 1 | I14: comet_neowise | J14: observation-default | K14: Comète C/2020 F3 NEOWISE | L14: Comet | M14: C/2020 F3 | N14: sky_event | O14: Comete non periodique | P14: Variable | Q14: Ete | R14: 0 | S14: 0 | T14: 0 | U14: AD 00h 00m 00,0s | V14: + | W14: 0 | X14: 0 | Y14: 0 | Z14: +00° 00′ 00″ | AA14: AD 00h 00m 00,0s ; Dec +00° 00′ 00″ | AB14: Comète très médiatisée en 2020, connue pour sa belle queue visible à l'oeil nu. | AC14: sky_event | AU14: 0.9 | AV14: mag. 0,9 max. 2020
A15: card | B15: astronomes-en-herbe | E15: aeh-cygne | F15: Cygne | G15: Common | H15: 1 | I15: cygnus_constellation | J15: observation-default | K15: Cygne | L15: IAU | M15: CYG | N15: constellation | O15: Constellation | P15: Cygne | Q15: Ete | R15: 20 | S15: 30 | T15: 0 | U15: AD 20h 30m 00,0s | V15: + | W15: 42 | X15: 0 | Y15: 0 | Z15: +42° 00′ 00″ | AA15: AD 20h 30m 00,0s ; Dec +42° 00′ 00″ | AB15: Grande constellation en croix, bien visible l'été le long de la Voie lactée. | AC15: constellation | AH15: 12 | AI15: 9 | AJ15: 6 | AK15: 0 | AL15: 0 | AM15: 6°00′00″ | AN15: 4 | AO15: 30 | AP15: 0 | AQ15: 4°30′00″ | AR15: 12,00 × 9,00 (6°00′00″ × 4°30′00″)
A16: card | B16: astronomes-en-herbe | E16: aeh-double-cluster | F16: Double Amas de Persée | G16: Common | H16: 1 | I16: double_cluster | J16: observation-default | K16: Double Amas de Persée | L16: Caldwell | M16: C14 | N16: deep_sky | O16: Double amas ouvert | P16: Persee | Q16: Automne | R16: 2 | S16: 21 | T16: 0 | U16: AD 02h 21m 00,0s | V16: + | W16: 57 | X16: 8 | Y16: 0 | Z16: +57° 08′ 00″ | AA16: AD 02h 21m 00,0s ; Dec +57° 08′ 00″ | AB16: Deux amas d'étoiles serrés l'un contre l'autre, célèbres pour leur beau rendu aux jumelles. | AC16: deep_sky | AD16: 7500 | AE16: 7 500 annees-lumiere | AF16: 70 | AG16: 70 annees-lumiere | AH16: 2 | AI16: 1 | AJ16: 1 | AK16: 0 | AL16: 0 | AM16: 1°00′00″ | AN16: 0 | AO16: 30 | AP16: 0 | AQ16: 0°30′00″ | AR16: 2,00 × 1,00 (1°00′00″ × 0°30′00″) | AS16: -3.7 | AT16: -3.7 | AU16: 3.7 | AV16: 3.7 / 3.8
A17: card | B17: astronomes-en-herbe | E17: aeh-gemeaux | F17: Gémeaux | G17: Common | H17: 1 | I17: gemini_constellation | J17: observation-default | K17: Gémeaux | L17: IAU | M17: GEM | N17: constellation | O17: Constellation | P17: Gemeaux | Q17: Hiver | R17: 7 | S17: 0 | T17: 0 | U17: AD 07h 00m 00,0s | V17: + | W17: 22 | X17: 0 | Y17: 0 | Z17: +22° 00′ 00″ | AA17: AD 07h 00m 00,0s ; Dec +22° 00′ 00″ | AB17: Constellation marquée par Castor et Pollux, facile à identifier en hiver. | AC17: constellation | AH17: 9 | AI17: 6 | AJ17: 4 | AK17: 30 | AL17: 0 | AM17: 4°30′00″ | AN17: 3 | AO17: 0 | AP17: 0 | AQ17: 3°00′00″ | AR17: 9,00 × 6,00 (4°30′00″ × 3°00′00″)
A18: card | B18: astronomes-en-herbe | E18: aeh-geminids | F18: Géminides | G18: Uncommon | H18: 1 | I18: geminids_meteor_shower | J18: observation-default | K18: Géminides | L18: IMO | M18: GEM | N18: sky_event | O18: Essaim d'etoiles filantes | P18: Gemeaux | Q18: Hiver | R18: 7 | S18: 30 | T18: 0 | U18: AD 07h 30m 00,0s | V18: + | W18: 32 | X18: 0 | Y18: 0 | Z18: +32° 00′ 00″ | AA18: AD 07h 30m 00,0s ; Dec +32° 00′ 00″ | AB18: Pluie d'étoiles filantes très active de décembre, connue pour ses nombreux météores brillants. | AC18: sky_event | AH18: 180 | AI18: 90 | AJ18: 90 | AK18: 0 | AL18: 0 | AM18: 90°00′00″ | AN18: 45 | AO18: 0 | AP18: 0 | AQ18: 45°00′00″ | AR18: 180,00 × 90,00 (90°00′00″ × 45°00′00″)
A19: card | B19: astronomes-en-herbe | E19: aeh-comet-halley | F19: Comète de Halley | G19: Epic | H19: 1 | I19: halley_comet | J19: observation-default | K19: Comète de Halley | L19: Periodic Comet | M19: 1P/Halley | N19: sky_event | O19: Comete periodique | P19: Variable | Q19: Variable | R19: 0 | S19: 0 | T19: 0 | U19: AD 00h 00m 00,0s | V19: + | W19: 0 | X19: 0 | Y19: 0 | Z19: +00° 00′ 00″ | AA19: AD 00h 00m 00,0s ; Dec +00° 00′ 00″ | AB19: Comète la plus célèbre du ciel, connue pour revenir environ tous les 76 ans. | AC19: sky_event | AU19: 2.1 | AV19: mag. 2,1 max. 1986
A20: card | B20: astronomes-en-herbe | E20: aeh-hyades | F20: Hyades | G20: Common | H20: 1 | I20: hyades | J20: observation-default | K20: Hyades | L20: Melotte | M20: Mel 25 | N20: deep_sky | O20: Amas ouvert | P20: Taureau | Q20: Hiver | R20: 4 | S20: 27 | T20: 0 | U20: AD 04h 27m 00,0s | V20: + | W20: 16 | X20: 0 | Y20: 0 | Z20: +16° 00′ 00″ | AA20: AD 04h 27m 00,0s ; Dec +16° 00′ 00″ | AB20: Nymphes des pluies dans la mythologie grec, c'est un grand amas d'étoiles dans la constellation du Taureau formant un V, très facile à voir à l'oeil nu. | AC20: deep_sky | AD20: 153 | AE20: 153 annees-lumiere | AF20: 75 | AG20: 75 annees-lumiere | AH20: 11 | AI20: 5 | AJ20: 5 | AK20: 30 | AL20: 0 | AM20: 5°30′00″ | AN20: 2 | AO20: 30 | AP20: 0 | AQ20: 2°30′00″ | AR20: 11,00 × 5,00 (5°30′00″ × 2°30′00″) | AS20: -2.7 | AT20: -2.7 | AU20: 0.5 | AV20: 0.5
A21: card | B21: astronomes-en-herbe | E21: aeh-leonids | F21: Léonides | G21: Uncommon | H21: 1 | I21: leonids_meteor_shower | J21: observation-default | K21: Léonides | L21: IMO | M21: LEO | N21: sky_event | O21: Essaim d'etoiles filantes | P21: Lion | Q21: Automne | R21: 10 | S21: 8 | T21: 0 | U21: AD 10h 08m 00,0s | V21: + | W21: 22 | X21: 0 | Y21: 0 | Z21: +22° 00′ 00″ | AA21: AD 10h 08m 00,0s ; Dec +22° 00′ 00″ | AB21: Pluie d'étoiles filantes de novembre dont le radiant se trouve dans la constellation du Lion. | AC21: sky_event | AH21: 174.19 | AI21: 87.1 | AJ21: 90 | AK21: 0 | AL21: 0 | AM21: 90°00′00″ | AN21: 45 | AO21: 0 | AP21: 0 | AQ21: 45°00′00″ | AR21: 174,19 × 87,10 (90°00′00″ × 45°00′00″)
A22: card | B22: astronomes-en-herbe | E22: aeh-lyre-constellation | F22: Lyre | G22: Common | H22: 1 | I22: lyra_constellation | J22: observation-default | K22: Lyre | L22: IAU | M22: LYR | N22: constellation | O22: Constellation | P22: Lyre | Q22: Ete | R22: 18 | S22: 50 | T22: 0 | U22: AD 18h 50m 00,0s | V22: + | W22: 36 | X22: 40 | Y22: 0 | Z22: +36° 40′ 00″ | AA22: AD 18h 50m 00,0s ; Dec +36° 40′ 00″ | AB22: Petite constellation facile à retrouver grâce à Véga, très connue en été. | AC22: constellation | AH22: 7.74 | AI22: 5.81 | AJ22: 4 | AK22: 0 | AL22: 0 | AM22: 4°00′00″ | AN22: 3 | AO22: 0 | AP22: 0 | AQ22: 3°00′00″ | AR22: 7,74 × 5,81 (4°00′00″ × 3°00′00″)
A23: card | B23: astronomes-en-herbe | E23: aeh-m11-wild-duck | F23: Amas du Canard Sauvage | G23: Uncommon | H23: 1 | I23: m11_wild_duck_cluster | J23: observation-default | K23: Amas du Canard Sauvage | L23: Messier | M23: M11 | N23: deep_sky | O23: Amas ouvert | P23: Ecu | Q23: Ete | R23: 18 | S23: 51 | T23: 6 | U23: AD 18h 51m 06,0s | V23: - | W23: 6 | X23: 16 | Y23: 0 | Z23: -06° 16′ 00″ | AA23: AD 18h 51m 06,0s ; Dec -06° 16′ 00″ | AB23: Amas ouvert très dense, célèbre pour son aspect compact dans des jumelles. | AC23: deep_sky | AD23: 6120 | AE23: 6 120 annees-lumiere | AF23: 20 | AG23: 20 annees-lumiere | AH23: 0.45 | AI23: 0.45 | AJ23: 0 | AK23: 14 | AL23: 0 | AM23: 0°14′00″ | AN23: 0 | AO23: 14 | AP23: 0 | AQ23: 0°14′00″ | AR23: 0,45 × 0,45 (0°14′00″ × 0°14′00″) | AS23: -6.3 | AT23: -6.3 | AU23: 5.8 | AV23: 5.8
A24: card | B24: astronomes-en-herbe | E24: aeh-m13-hercules | F24: Grand amas d'Hercule | G24: Uncommon | H24: 1 | I24: m13_hercules | J24: observation-default | K24: Grand amas d'Hercule | L24: Messier | M24: M13 | N24: deep_sky | O24: Amas globulaire | P24: Hercule | Q24: Ete | R24: 16 | S24: 41 | T24: 41 | U24: AD 16h 41m 41,0s | V24: + | W24: 36 | X24: 28 | Y24: 0 | Z24: +36° 28′ 00″ | AA24: AD 16h 41m 41,0s ; Dec +36° 28′ 00″ | AB24: Amas globulaire très connu de l'hémisphère nord, facile à trouver entre les étoiles d'Hercule. | AC24: deep_sky | AD24: 25000 | AE24: 25 000 annees-lumiere | AF24: 145 | AG24: 145 annees-lumiere | AH24: 0.65 | AI24: 0.65 | AJ24: 0 | AK24: 20 | AL24: 0 | AM24: 0°20′00″ | AN24: 0 | AO24: 20 | AP24: 0 | AQ24: 0°20′00″ | AR24: 0,65 × 0,65 (0°20′00″ × 0°20′00″) | AS24: -8.5 | AT24: -8.5 | AU24: 5.8 | AV24: 5.8
A25: card | B25: astronomes-en-herbe | E25: aeh-m16-eagle | F25: Nébuleuse de l'Aigle | G25: Rare | H25: 1 | I25: m16_eagle_nebula | J25: observation-default | K25: Nébuleuse de l'Aigle | L25: Messier | M25: M16 | N25: deep_sky | O25: Amas ouvert et nebuleuse | P25: Serpent | Q25: Ete | R25: 18 | S25: 18 | T25: 48 | U25: AD 18h 18m 48,0s | V25: - | W25: 13 | X25: 49 | Y25: 0 | Z25: -13° 49′ 00″ | AA25: AD 18h 18m 48,0s ; Dec -13° 49′ 00″ | AB25: Amas d'étoiles et nébuleuse au centre de laquelle se trouve les Piliers de la Création. | AC25: deep_sky | AD25: 5700 | AE25: 5 700 annees-lumiere | AF25: 70 | AG25: 70 annees-lumiere | AH25: 1.13 | AI25: 0.9 | AJ25: 0 | AK25: 35 | AL25: 0 | AM25: 0°35′00″ | AN25: 0 | AO25: 28 | AP25: 0 | AQ25: 0°28′00″ | AR25: 1,13 × 0,90 (0°35′00″ × 0°28′00″) | AS25: -6.4 | AT25: -6.4 | AU25: 6.4 | AV25: 6.4
A26: card | B26: astronomes-en-herbe | E26: aeh-m17-swan | F26: Nébuleuse Oméga | G26: Rare | H26: 1 | I26: m17_swan_nebula | J26: observation-default | K26: Nébuleuse Oméga | L26: Messier | M26: M17 | N26: deep_sky | O26: Nebuleuse diffuse | P26: Sagittaire | Q26: Ete | R26: 18 | S26: 20 | T26: 47 | U26: AD 18h 20m 47,0s | V26: - | W26: 16 | X26: 11 | Y26: 0 | Z26: -16° 11′ 00″ | AA26: AD 18h 20m 47,0s ; Dec -16° 11′ 00″ | AB26: Nébuleuse brillante de la Voie lactée d'été dont la forme se rapproche de la lettre grec Ω ou d'un fer à cheval. | AC26: deep_sky | AD26: 5500 | AE26: 5 500 annees-lumiere | AF26: 15 | AG26: 15 annees-lumiere | AH26: 0.65 | AI26: 0.48 | AJ26: 0 | AK26: 20 | AL26: 0 | AM26: 0°20′00″ | AN26: 0 | AO26: 15 | AP26: 0 | AQ26: 0°15′00″ | AR26: 0,65 × 0,48 (0°20′00″ × 0°15′00″) | AS26: -5.8 | AT26: -5.8 | AU26: 6 | AV26: 6.0
A27: card | B27: astronomes-en-herbe | E27: aeh-m22-globular | F27: M22 | G27: Uncommon | H27: 1 | I27: m22_globular_cluster | J27: observation-default | K27: M22 | L27: Messier | M27: M22 | N27: deep_sky | O27: Amas globulaire | P27: Sagittaire | Q27: Ete | R27: 18 | S27: 36 | T27: 24 | U27: AD 18h 36m 24,0s | V27: - | W27: 23 | X27: 54 | Y27: 0 | Z27: -23° 54′ 00″ | AA27: AD 18h 36m 24,0s ; Dec -23° 54′ 00″ | AB27: Un des plus beaux amas globulaires du ciel, brillant et facile à trouver. | AC27: deep_sky | AD27: 10600 | AE27: 10 600 annees-lumiere | AF27: 100 | AG27: 100 annees-lumiere | AH27: 0.77 | AI27: 0.77 | AJ27: 0 | AK27: 24 | AL27: 0 | AM27: 0°24′00″ | AN27: 0 | AO27: 24 | AP27: 0 | AQ27: 0°24′00″ | AR27: 0,77 × 0,77 (0°24′00″ × 0°24′00″) | AS27: -8.5 | AT27: -8.5 | AU27: 5.1 | AV27: 5.1
A28: card | B28: astronomes-en-herbe | E28: aeh-m24-star-cloud | F28: Nuage stellaire du Sagittaire | G28: Common | H28: 1 | I28: m24_star_cloud | J28: observation-default | K28: Nuage Stellaire du Sagittaire | L28: Messier | M28: M24 | N28: deep_sky | O28: Nuage stellaire | P28: Sagittaire | Q28: Ete | R28: 18 | S28: 16 | T28: 48 | U28: AD 18h 16m 48,0s | V28: - | W28: 18 | X28: 29 | Y28: 0 | Z28: -18° 29′ 00″ | AA28: AD 18h 16m 48,0s ; Dec -18° 29′ 00″ | AB28: Zone très riche de la Voie lactée, ce n'est pas un véritablement un amas d'étoiles et est souvent considéré comme une erreur du Catalogue de Messier. | AC28: deep_sky | AD28: 10000 | AE28: 10 000 annees-lumiere | AF28: 600 | AG28: 600 annees-lumiere | AH28: 3.87 | AI28: 1.94 | AJ28: 2 | AK28: 0 | AL28: 0 | AM28: 2°00′00″ | AN28: 1 | AO28: 0 | AP28: 0 | AQ28: 1°00′00″ | AR28: 3,87 × 1,94 (2°00′00″ × 1°00′00″) | AU28: 2.5 | AV28: 2.5
A29: card | B29: astronomes-en-herbe | E29: aeh-m27-dumbbell | F29: Nébuleuse de l'Haltère | G29: Uncommon | H29: 1 | I29: m27_dumbbell | J29: observation-default | K29: Nébuleuse de l'Haltère | L29: Messier | M29: M27 | N29: deep_sky | O29: Nebuleuse planetaire | P29: Petit Renard | Q29: Ete | R29: 19 | S29: 59 | T29: 36 | U29: AD 19h 59m 36,0s | V29: + | W29: 22 | X29: 43 | Y29: 0 | Z29: +22° 43′ 00″ | AA29: AD 19h 59m 36,0s ; Dec +22° 43′ 00″ | AB29: Nébuleuse planétaire célèbre pour sa forme d'haltère, accessible avec un petit télescope. | AC29: deep_sky | AD29: 1360 | AE29: 1 360 annees-lumiere | AF29: 2.5 | AG29: 2,5 annees-lumiere | AH29: 0.27 | AI29: 0.18 | AJ29: 0 | AK29: 8 | AL29: 0 | AM29: 0°08′00″ | AN29: 0 | AO29: 5 | AP29: 0 | AQ29: 0°05′00″ | AR29: 0,27 × 0,18 (0°08′00″ × 0°05′00″) | AS29: -0.5 | AT29: -0.5 | AU29: 7.4 | AV29: 7.4
A30: card | B30: astronomes-en-herbe | E30: aeh-m31-andromeda | F30: Galaxie d'Andromède | G30: Common | H30: 1 | I30: m31_andromeda | J30: observation-default | K30: Galaxie d'Andromède | L30: Messier | M30: M31 | N30: deep_sky | O30: Galaxie spirale | P30: Andromede | Q30: Automne | R30: 0 | S30: 42 | T30: 44.3 | U30: AD 00h 42m 44,3s | V30: + | W30: 41 | X30: 16 | Y30: 9 | Z30: +41° 16′ 09″ | AA30: AD 00h 42m 44,3s ; Dec +41° 16′ 09″ | AB30: Grande galaxie voisine de la Voie lactée, c'est l'objet le plus lointain qui est visible à l'oeil nu sous un bon ciel. | AC30: deep_sky | AD30: 2540000 | AE30: 2 540 000 annees-lumiere | AF30: 220000 | AG30: 220 000 annees-lumiere | AH30: 6 | AI30: 2 | AJ30: 3 | AK30: 0 | AL30: 0 | AM30: 3°00′00″ | AN30: 1 | AO30: 0 | AP30: 0 | AQ30: 1°00′00″ | AR30: 6,00 × 2,00 (3°00′00″ × 1°00′00″) | AS30: -21.5 | AT30: -21.5 | AU30: 3.44 | AV30: 3.44
A31: card | B31: astronomes-en-herbe | E31: aeh-m33-triangulum | F31: Galaxie du Triangle | G31: Rare | H31: 1 | I31: m33_triangulum | J31: observation-default | K31: Galaxie du Triangle | L31: Messier | M31: M33 | N31: deep_sky | O31: Galaxie spirale | P31: Triangle | Q31: Automne | R31: 1 | S31: 33 | T31: 51 | U31: AD 01h 33m 51,0s | V31: + | W31: 30 | X31: 39 | Y31: 37 | Z31: +30° 39′ 37″ | AA31: AD 01h 33m 51,0s ; Dec +30° 39′ 37″ | AB31: Grande galaxie voisine du Groupe local, célèbre mais plus difficile à voir que M31 (galaxie d'Andromède). | AC31: deep_sky | AD31: 2730000 | AE31: 2 730 000 annees-lumiere | AF31: 60000 | AG31: 60 000 annees-lumiere | AH31: 2.3 | AI31: 1.5 | AJ31: 1 | AK31: 8 | AL31: 0 | AM31: 1°08′00″ | AN31: 0 | AO31: 45 | AP31: 0 | AQ31: 0°45′00″ | AR31: 2,30 × 1,50 (1°08′00″ × 0°45′00″) | AS31: -18.9 | AT31: -18.9 | AU31: 5.72 | AV31: 5.72
A32: card | B32: astronomes-en-herbe | E32: aeh-m37-open-cluster | F32: M37 | G32: Uncommon | H32: 1 | I32: m37_open_cluster | J32: observation-default | K32: M37 | L32: Messier | M32: M37 | N32: deep_sky | O32: Amas ouvert | P32: Cocher | Q32: Hiver | R32: 5 | S32: 52 | T32: 18 | U32: AD 05h 52m 18,0s | V32: + | W32: 32 | X32: 33 | Y32: 0 | Z32: +32° 33′ 00″ | AA32: AD 05h 52m 18,0s ; Dec +32° 33′ 00″ | AB32: Amas d'étoiles ouvert riche et serré, souvent considéré comme le plus beau trio du Cocher. | AC32: deep_sky | AD32: 4500 | AE32: 4 500 annees-lumiere | AF32: 25 | AG32: 25 annees-lumiere | AH32: 0.77 | AI32: 0.77 | AJ32: 0 | AK32: 24 | AL32: 0 | AM32: 0°24′00″ | AN32: 0 | AO32: 24 | AP32: 0 | AQ32: 0°24′00″ | AR32: 0,77 × 0,77 (0°24′00″ × 0°24′00″) | AS32: -5 | AT32: -5 | AU32: 6.2 | AV32: 6.2
A33: card | B33: astronomes-en-herbe | E33: aeh-m38-open-cluster | F33: M38 | G33: Uncommon | H33: 1 | I33: m38_open_cluster | J33: observation-default | K33: M38 | L33: Messier | M33: M38 | N33: deep_sky | O33: Amas ouvert | P33: Cocher | Q33: Hiver | R33: 5 | S33: 28 | T33: 42 | U33: AD 05h 28m 42,0s | V33: + | W33: 35 | X33: 51 | Y33: 0 | Z33: +35° 51′ 00″ | AA33: AD 05h 28m 42,0s ; Dec +35° 51′ 00″ | AB33: Amas d'étoiles ouvert large du Cocher, facile à compléter avec M36 et M37. | AC33: deep_sky | AD33: 4200 | AE33: 4 200 annees-lumiere | AF33: 25 | AG33: 25 annees-lumiere | AH33: 0.68 | AI33: 0.68 | AJ33: 0 | AK33: 21 | AL33: 0 | AM33: 0°21′00″ | AN33: 0 | AO33: 21 | AP33: 0 | AQ33: 0°21′00″ | AR33: 0,68 × 0,68 (0°21′00″ × 0°21′00″) | AS33: -4.2 | AT33: -4.2 | AU33: 7.4 | AV33: 7.4
A34: card | B34: astronomes-en-herbe | E34: aeh-m39-open-cluster | F34: M39 | G34: Common | H34: 1 | I34: m39_open_cluster | J34: observation-default | K34: M39 | L34: Messier | M34: M39 | N34: deep_sky | O34: Amas ouvert | P34: Cygne | Q34: Ete | R34: 21 | S34: 31 | T34: 48 | U34: AD 21h 31m 48,0s | V34: + | W34: 48 | X34: 26 | Y34: 0 | Z34: +48° 26′ 00″ | AA34: AD 21h 31m 48,0s ; Dec +48° 26′ 00″ | AB34: Amas d'étoiles ouvert large et détendu, facile aux jumelles dans le Cygne. | AC34: deep_sky | AD34: 1010 | AE34: 1 010 annees-lumiere | AF34: 7 | AG34: 7 annees-lumiere | AH34: 1.03 | AI34: 1.03 | AJ34: 0 | AK34: 32 | AL34: 0 | AM34: 0°32′00″ | AN34: 0 | AO34: 32 | AP34: 0 | AQ34: 0°32′00″ | AR34: 1,03 × 1,03 (0°32′00″ × 0°32′00″) | AS34: -4.2 | AT34: -4.2 | AU34: 4.6 | AV34: 4.6
A35: card | B35: astronomes-en-herbe | E35: aeh-m41-open-cluster | F35: M41 | G35: Common | H35: 1 | I35: m41_open_cluster | J35: observation-default | K35: M41 | L35: Messier | M35: M41 | N35: deep_sky | O35: Amas ouvert | P35: Grand Chien | Q35: Hiver | R35: 6 | S35: 47 | T35: 0 | U35: AD 06h 47m 00,0s | V35: - | W35: 20 | X35: 44 | Y35: 0 | Z35: -20° 44′ 00″ | AA35: AD 06h 47m 00,0s ; Dec -20° 44′ 00″ | AB35: Amas ouvert facile à trouver sous Sirius, joli aux jumelles. | AC35: deep_sky | AD35: 2300 | AE35: 2 300 annees-lumiere | AF35: 25 | AG35: 25 annees-lumiere | AH35: 1.23 | AI35: 1.23 | AJ35: 0 | AK35: 38 | AL35: 0 | AM35: 0°38′00″ | AN35: 0 | AO35: 38 | AP35: 0 | AQ35: 0°38′00″ | AR35: 1,23 × 1,23 (0°38′00″ × 0°38′00″) | AS35: -4.2 | AT35: -4.2 | AU35: 4.5 | AV35: 4.5
A36: card | B36: astronomes-en-herbe | E36: aeh-m42-orion-nebula | F36: Nébuleuse d'Orion | G36: Common | H36: 1 | I36: m42_orion_nebula | J36: observation-default | K36: Nébuleuse d'Orion | L36: Messier | M36: M42 | N36: deep_sky | O36: Nebuleuse par emission et reflexion | P36: Orion | Q36: Hiver | R36: 5 | S36: 35 | T36: 17.3 | U36: AD 05h 35m 17,3s | V36: - | W36: 5 | X36: 23 | Y36: 28 | Z36: -05° 23′ 28″ | AA36: AD 05h 35m 17,3s ; Dec -05° 23′ 28″ | AB36: Nébuleuse très célèbre sous la ceinture d'Orion et visible à l'œil nu. Elle est une cible privilégiée pour les astronomes débutants. | AC36: deep_sky | AD36: 1344 | AE36: 1 344 annees-lumiere | AF36: 24 | AG36: 24 annees-lumiere | AH36: 2.1 | AI36: 1.94 | AJ36: 1 | AK36: 5 | AL36: 0 | AM36: 1°05′00″ | AN36: 1 | AO36: 0 | AP36: 0 | AQ36: 1°00′00″ | AR36: 2,10 × 1,94 (1°05′00″ × 1°00′00″) | AS36: -4.1 | AT36: -4.1 | AU36: 4 | AV36: 4.0
A37: card | B37: astronomes-en-herbe | E37: aeh-m45-pleiades | F37: Pléïades | G37: Common | H37: 1 | I37: m45_pleiades | J37: observation-default | K37: Pléïades | L37: Messier | M37: M45 | N37: deep_sky | O37: Amas ouvert | P37: Taureau | Q37: Hiver | R37: 3 | S37: 47 | T37: 24 | U37: AD 03h 47m 24,0s | V37: + | W37: 24 | X37: 7 | Y37: 0 | Z37: +24° 07′ 00″ | AA37: AD 03h 47m 24,0s ; Dec +24° 07′ 00″ | AB37: Aussi appelé "Sept Sœurs" par les anglophones, on dit que cet amas d'étoiles ouvert servait de test d'acuité visuel dans l'Antiquité. | AC37: deep_sky | AD37: 444 | AE37: 444 annees-lumiere | AF37: 17.5 | AG37: 17,5 annees-lumiere | AH37: 3.67 | AI37: 3.67 | AJ37: 1 | AK37: 50 | AL37: 0 | AM37: 1°50′00″ | AN37: 1 | AO37: 50 | AP37: 0 | AQ37: 1°50′00″ | AR37: 3,67 × 3,67 (1°50′00″ × 1°50′00″) | AS37: -1.6 | AT37: -1.6 | AU37: 1.6 | AV37: 1.6
A38: card | B38: astronomes-en-herbe | E38: aeh-m46-open-cluster | F38: M46 | G38: Uncommon | H38: 1 | I38: m46_open_cluster | J38: observation-default | K38: M46 | L38: Messier | M38: M46 | N38: deep_sky | O38: Amas ouvert | P38: Poupe | Q38: Hiver | R38: 7 | S38: 41 | T38: 46 | U38: AD 07h 41m 46,0s | V38: - | W38: 14 | X38: 49 | Y38: 0 | Z38: -14° 49′ 00″ | AA38: AD 07h 41m 46,0s ; Dec -14° 49′ 00″ | AB38: Amas d'étoiles ouvert partageant le ciel avec un nébuleuse planétaire. Elles ne sont cependant pas physiquement au même endroit. | AC38: deep_sky | AD38: 4900 | AE38: 4 900 annees-lumiere | AF38: 30 | AG38: 30 annees-lumiere | AH38: 0.87 | AI38: 0.87 | AJ38: 0 | AK38: 27 | AL38: 0 | AM38: 0°27′00″ | AN38: 0 | AO38: 27 | AP38: 0 | AQ38: 0°27′00″ | AR38: 0,87 × 0,87 (0°27′00″ × 0°27′00″) | AS38: -6.1 | AT38: -6.1 | AU38: 6 | AV38: 6.0
A39: card | B39: astronomes-en-herbe | E39: aeh-m57-ring | F39: Nébuleuse de la Lyre | G39: Rare | H39: 1 | I39: m57_ring | J39: observation-default | K39: Nébuleuse de la Lyre | L39: Messier | M39: M57 | N39: deep_sky | O39: Nebuleuse planetaire | P39: Lyre | Q39: Ete | R39: 18 | S39: 53 | T39: 35 | U39: AD 18h 53m 35,0s | V39: + | W39: 33 | X39: 2 | Y39: 0 | Z39: +33° 02′ 00″ | AA39: AD 18h 53m 35,0s ; Dec +33° 02′ 00″ | AB39: Nébuleuse planétaire fameuse pour son anneau, facile à localiser entre les étoiles de la Lyre. | AC39: deep_sky | AD39: 2300 | AE39: 2 300 annees-lumiere | AF39: 1.3 | AG39: 1,3 annees-lumiere | AH39: 0.05 | AI39: 0.04 | AJ39: 0 | AK39: 1 | AL39: 24 | AM39: 0°01′24″ | AN39: 0 | AO39: 1 | AP39: 12 | AQ39: 0°01′12″ | AR39: 0,05 × 0,04 (0°01′24″ × 0°01′12″) | AS39: 0.7 | AT39: 0.7 | AU39: 8.8 | AV39: 8.8
A40: card | B40: astronomes-en-herbe | E40: aeh-m6-butterfly | F40: Amas du Papillon | G40: Uncommon | H40: 1 | I40: m6_butterfly_cluster | J40: observation-default | K40: Amas du Papillon | L40: Messier | M40: M6 | N40: deep_sky | O40: Amas ouvert | P40: Scorpion | Q40: Ete | R40: 17 | S40: 40 | T40: 12 | U40: AD 17h 40m 12,0s | V40: - | W40: 32 | X40: 13 | Y40: 0 | Z40: -32° 13′ 00″ | AA40: AD 17h 40m 12,0s ; Dec -32° 13′ 00″ | AB40: Amas ouvert célèbre pour sa forme de papillon. | AC40: deep_sky | AD40: 1600 | AE40: 1 600 annees-lumiere | AF40: 20 | AG40: 20 annees-lumiere | AH40: 0.81 | AI40: 0.81 | AJ40: 0 | AK40: 25 | AL40: 0 | AM40: 0°25′00″ | AN40: 0 | AO40: 25 | AP40: 0 | AQ40: 0°25′00″ | AR40: 0,81 × 0,81 (0°25′00″ × 0°25′00″) | AS40: -5.6 | AT40: -5.6 | AU40: 4.2 | AV40: 4.2
...

Sheet Equipements
A1: equipmentCardId | B1: equipmentType | C1: displayName | D1: level | E1: imageRef | F1: packsAffected | G1: bonusValue | H1: bonusUnit | I1: dropWeight | J1: description
A2: observatory-beginner | B2: observatory | C2: Abri d'observation | D2: 1 | E2: equipment_observatory_1 | F2: 2 | G2: 1.25 | H2: rechargeMultiplier | I2: 16 | J2: Accélère légèrement la recharge des packs.
A3: observatory-advanced | B3: observatory | C3: Dôme motorisé | D3: 2 | E3: equipment_observatory_2 | F3: 3 | G3: 1.5 | H3: rechargeMultiplier | I3: 10 | J3: Maintient une recharge plus rapide pendant plusieurs packs.
A4: observatory-master | B4: observatory | C4: Observatoire de recherche | D4: 3 | E4: equipment_observatory_3 | F4: 4 | G4: 2 | H4: rechargeMultiplier | I4: 4 | J4: Double la vitesse de recharge pour une courte série de packs.
A5: telescope-beginner | B5: telescope | C5: Newton | D5: 1 | E5: equipment_telescope_1 | F5: 2 | G5: 8 | H5: holographicSkyPercent | I5: 16 | J5: Ajoute une petite chance holographique supplémentaire.
A6: telescope-advanced | B6: telescope | C6: Lunette apochromatique | D6: 2 | E6: equipment_telescope_2 | F6: 3 | G6: 12 | H6: holographicSkyPercent | I6: 10 | J6: Renforce sensiblement l'apparition des cartes holographiques.
A7: telescope-master | B7: telescope | C7: Ritchey-Chrétien | D7: 3 | E7: equipment_telescope_3 | F7: 4 | G7: 18 | H7: holographicSkyPercent | I7: 4 | J7: Offre une forte poussée holographique sur les prochains packs.
A8: mount-beginner | B8: mount | C8: Monture Alt-Az | D8: 1 | E8: equipment_mount_1 | F8: 2 | G8: 6 | H8: rarityBoost | I8: 16 | J8: Ajoute une chance modérée de promouvoir une carte d'un palier.
A9: mount-advanced | B9: mount | C9: Monture équatoriale | D9: 2 | E9: equipment_mount_2 | F9: 3 | G9: 10 | H9: rarityBoost | I9: 10 | J9: Augmente davantage la probabilité de gagner en rareté.
A10: mount-master | B10: mount | C10: Monture harmonique | D10: 3 | E10: equipment_mount_3 | F10: 4 | G10: 15 | H10: rarityBoost | I10: 4 | J10: Améliore grandement la probabilité de gagner en rareté.

Sheet Donnees
A1: GlobalSettings
A3: cardsPerDraw | B3: 5 | D3: cardsPerDay
A4: drawCooldownHours | B4: 6 | D4: =B3*24/B4 -> 20
A6: villeMeanPerDay | B6: =B3*24/B4-SUM(B7:B10) -> 9.8571429
A7: suburbanMeanPerDay | B7: 6
A8: ruralMeanPerDay | B8: 3
A9: mountainMeanPerDay | B9: 1
A10: holoMeanPerDay | B10: =1/7 -> 0.14285714 | D10: percentStampMeanPerDay
A11: unstampMeanPerDay | B11: =D4-B12 -> 18 | D11: 10
A12: stampMeanPerDay | B12: =D11*D4/100 -> 2
A14: commonPerDay | B14: =$D$4*E14/100 -> 10 | D14: percentCommonPerDay | E14: =100-SUM(E15:E17) -> 50 | G14: commonHoloMeanDays | H14: =1/(B14*$D$11/100) -> 1
A15: uncommonPerDay | B15: =$D$4*E15/100 -> 6 | D15: percentUncommonPerDay | E15: 30 | G15: uncommonHoloMeanDays | H15: =1/(B15*$D$11/100) -> 1.6666667
A16: rarePerDay | B16: =$D$4*E16/100 -> 3 | D16: percentRarePerDay | E16: 15 | G16: rareHoloMeanDays | H16: =1/(B16*$D$11/100) -> 3.3333333
A17: epicPerDay | B17: =$D$4*E17/100 -> 1 | D17: percentEpicPerDay | E17: 5 | G17: epicHoloMeanDays | H17: =1/(B17*$D$11/100) -> 10
A19: EquipmentChancePercent | B19: 5

Sheet Resultats
A1: VariantProfiles
A2: variantProfileId | B2: category | C2: code | D2: label | E2: weight | F2: probability | G2: meanPacks | H2: meanDays
A3: observation-default | B3: skyQuality | C3: city | D3: Ville | E3: =Donnees!B6 -> 9.8571429 | F3: =E3/SUMPRODUCT($E$3:$E$7) -> 0.49285714 | G3: =1/(F3*Donnees!$B$3) -> 0.4057971 | H3: =1/(1/G3*24/Donnees!$B$4) -> 0.10144928
A4: observation-default | B4: skyQuality | C4: suburban | D4: Periurbain | E4: =Donnees!B7 -> 6 | F4: =E4/SUMPRODUCT($E$3:$E$7) -> 0.3 | G4: =1/(F4*Donnees!$B$3) -> 0.66666667 | H4: =1/(1/G4*24/Donnees!$B$4) -> 0.16666667
A5: observation-default | B5: skyQuality | C5: rural | D5: Campagne | E5: =Donnees!B8 -> 3 | F5: =E5/SUMPRODUCT($E$3:$E$7) -> 0.15 | G5: =1/(F5*Donnees!$B$3) -> 1.3333333 | H5: =1/(1/G5*24/Donnees!$B$4) -> 0.33333333
A6: observation-default | B6: skyQuality | C6: mountain | D6: Montagne | E6: =Donnees!B9 -> 1 | F6: =E6/SUMPRODUCT($E$3:$E$7) -> 0.05 | G6: =1/(F6*Donnees!$B$3) -> 4 | H6: =1/(1/G6*24/Donnees!$B$4) -> 1
A7: observation-default | B7: skyQuality | C7: holographic | D7: Holographique | E7: =Donnees!B10 -> 0.14285714 | F7: =E7/SUMPRODUCT($E$3:$E$7) -> 0.0071428571 | G7: =1/(F7*Donnees!$B$3) -> 28 | H7: =1/(1/G7*24/Donnees!$B$4) -> 7
A8: observation-default | B8: finish | C8: standard | D8: Standard | E8: =Donnees!B11 -> 18 | F8: =E8/SUMPRODUCT(E$8:E$9) -> 0.9 | G8: =F8*Donnees!$B$3 -> 4.5 | H8: =G8*24/Donnees!$B$4 -> 18
A9: observation-default | B9: finish | C9: holographic | D9: Holographique | E9: =Donnees!B12 -> 2 | F9: =E9/SUMPRODUCT(E$8:E$9) -> 0.1 | G9: =F9*Donnees!$B$3 -> 0.5 | H9: =G9*24/Donnees!$B$4 -> 2
A11: RaritySummary
A12: rarityLabel | B12: cardCount | C12: totalWeight | D12: rarityProbability | E12: baseCardWeight | F12: rarityPerDays
A13: Common | B13: {=SUMPRODUCT(--(Table1[rowType]="card"),--(Table1[rarityLabel]=A13))} -> 48 | C13: {=SUMPRODUCT((Table1[rowType]="card")*(Table1[rarityLabel]=A13)*(Table1[cardRarityMultiplier]))*Donnees!B14} -> 480 | D13: =Donnees!E14/100 -> 0.5 | E13: =D13/B13 -> 0.010416667 | F13: =Donnees!$D$4*E13*B13 -> 10
A14: Uncommon | B14: {=SUMPRODUCT(--(Table1[rowType]="card"),--(Table1[rarityLabel]=A14))} -> 25 | C14: {=SUMPRODUCT((Table1[rowType]="card")*(Table1[rarityLabel]=A14)*(Table1[cardRarityMultiplier]))*Donnees!B15} -> 150 | D14: =Donnees!E15/100 -> 0.3 | E14: =D14/B14 -> 0.012 | F14: =Donnees!$D$4*E14*B14 -> 6
A15: Rare | B15: {=SUMPRODUCT(--(Table1[rowType]="card"),--(Table1[rarityLabel]=A15))} -> 17 | C15: {=SUMPRODUCT((Table1[rowType]="card")*(Table1[rarityLabel]=A15)*(Table1[cardRarityMultiplier]))*Donnees!B16} -> 51 | D15: =Donnees!E16/100 -> 0.15 | E15: =D15/B15 -> 0.0088235294 | F15: =Donnees!$D$4*E15*B15 -> 3
A16: Epic | B16: {=SUMPRODUCT(--(Table1[rowType]="card"),--(Table1[rarityLabel]=A16))} -> 8 | C16: {=SUMPRODUCT((Table1[rowType]="card")*(Table1[rarityLabel]=A16)*(Table1[cardRarityMultiplier]))*Donnees!B17} -> 8 | D16: =Donnees!E17/100 -> 0.05 | E16: =D16/B16 -> 0.00625 | F16: =Donnees!$D$4*E16*B16 -> 1
A18: Cards
A19: extensionId | B19: cardId | C19: name | D19: rarityLabel | E19: unnormedDrawWeight | F19: normalisedDrawWeight | G19: probabilityPerDay | H19: meanDays | I19: cityMD | J19: cityStampMD | K19: periMD | L19: periStampMD | M19: campMD | N19: campStampMD | O19: montMD | P19: montStampMD | Q19: holoMD | R19: holoStampMD
A20: astronomes-en-herbe | B20: aeh-albireo | C20: Albiréo | D20: Common | E20: =VLOOKUP(D20,$A$13:$F$16,5,FALSE)*_xlfn.XLOOKUP(Resultats!C20,Table1[name],Table1[cardRarityMultiplier]) -> 0.010416667 | F20: =E20/$E$118 -> 0.010483266 | G20: =1-POWER(1-E20,Donnees!$D$4) -> 0.18895034 | H20: =1/G20 -> 5.2923958 | I20: =1/(1-POWER(1-$F20*$F$3*$F$8,Donnees!$D$4)) -> 11.235257 | J20: =1/(1-POWER(1-$F20*$F$3*$F$9,Donnees!$D$4)) -> 97.248442 | K20: =1/(1-POWER(1-$F20*$F$4*$F$8,Donnees!$D$4)) -> 18.144549 | L20: =1/(1-POWER(1-$F20*$F$4*$F$9,Donnees!$D$4)) -> 159.45905 | M20: =1/(1-POWER(1-$F20*$F$5*$F$8,Donnees!$D$4)) -> 35.807028 | N20: =1/(1-POWER(1-$F20*$F$5*$F$9,Donnees!$D$4)) -> 318.44232 | O20: =1/(1-POWER(1-$F20*$F$6*$F$8,Donnees!$D$4)) -> 106.4648 | P20: =1/(1-POWER(1-$F20*$F$6*$F$9,Donnees!$D$4)) -> 954.37626 | Q20: =1/(1-POWER(1-$F20*$F$7*$F$8,Donnees!$D$4)) -> 742.39825 | R20: =1/(1-POWER(1-$F20*$F$7*$F$9,Donnees!$D$4)) -> 6677.7832
A21: astronomes-en-herbe | B21: aeh-algol | C21: Algol | D21: Uncommon | E21: =VLOOKUP(D21,$A$13:$F$16,5,FALSE)*_xlfn.XLOOKUP(Resultats!C21,Table1[name],Table1[cardRarityMultiplier]) -> 0.012 | F21: =E21/$E$118 -> 0.012076723 | G21: =1-POWER(1-E21,Donnees!$D$4) -> 0.2145132 | H21: =1/G21 -> 4.6617178 | I21: =1/(1-POWER(1-$F21*$F$3*$F$8,Donnees!$D$4)) -> 9.8177034 | J21: =1/(1-POWER(1-$F21*$F$3*$F$9,Donnees!$D$4)) -> 84.479968 | K21: =1/(1-POWER(1-$F21*$F$4*$F$8,Donnees!$D$4)) -> 15.814489 | L21: =1/(1-POWER(1-$F21*$F$4*$F$9,Donnees!$D$4)) -> 138.48214 | M21: =1/(1-POWER(1-$F21*$F$5*$F$8,Donnees!$D$4)) -> 31.145832 | N21: =1/(1-POWER(1-$F21*$F$5*$F$9,Donnees!$D$4)) -> 276.48837 | O21: =1/(1-POWER(1-$F21*$F$6*$F$8,Donnees!$D$4)) -> 92.480261 | P21: =1/(1-POWER(1-$F21*$F$6*$F$9,Donnees!$D$4)) -> 828.51432 | Q21: =1/(1-POWER(1-$F21*$F$7*$F$8,Donnees!$D$4)) -> 644.50563 | R21: =1/(1-POWER(1-$F21*$F$7*$F$9,Donnees!$D$4)) -> 5796.7495
A22: astronomes-en-herbe | B22: aeh-almach | C22: Almach | D22: Uncommon | E22: =VLOOKUP(D22,$A$13:$F$16,5,FALSE)*_xlfn.XLOOKUP(Resultats!C22,Table1[name],Table1[cardRarityMultiplier]) -> 0.012 | F22: =E22/$E$118 -> 0.012076723 | G22: =1-POWER(1-E22,Donnees!$D$4) -> 0.2145132 | H22: =1/G22 -> 4.6617178 | I22: =1/(1-POWER(1-$F22*$F$3*$F$8,Donnees!$D$4)) -> 9.8177034 | J22: =1/(1-POWER(1-$F22*$F$3*$F$9,Donnees!$D$4)) -> 84.479968 | K22: =1/(1-POWER(1-$F22*$F$4*$F$8,Donnees!$D$4)) -> 15.814489 | L22: =1/(1-POWER(1-$F22*$F$4*$F$9,Donnees!$D$4)) -> 138.48214 | M22: =1/(1-POWER(1-$F22*$F$5*$F$8,Donnees!$D$4)) -> 31.145832 | N22: =1/(1-POWER(1-$F22*$F$5*$F$9,Donnees!$D$4)) -> 276.48837 | O22: =1/(1-POWER(1-$F22*$F$6*$F$8,Donnees!$D$4)) -> 92.480261 | P22: =1/(1-POWER(1-$F22*$F$6*$F$9,Donnees!$D$4)) -> 828.51432 | Q22: =1/(1-POWER(1-$F22*$F$7*$F$8,Donnees!$D$4)) -> 644.50563 | R22: =1/(1-POWER(1-$F22*$F$7*$F$9,Donnees!$D$4)) -> 5796.7495
A23: astronomes-en-herbe | B23: aeh-altair | C23: Altaïr | D23: Common | E23: =VLOOKUP(D23,$A$13:$F$16,5,FALSE)*_xlfn.XLOOKUP(Resultats!C23,Table1[name],Table1[cardRarityMultiplier]) -> 0.010416667 | F23: =E23/$E$118 -> 0.010483266 | G23: =1-POWER(1-E23,Donnees!$D$4) -> 0.18895034 | H23: =1/G23 -> 5.2923958 | I23: =1/(1-POWER(1-$F23*$F$3*$F$8,Donnees!$D$4)) -> 11.235257 | J23: =1/(1-POWER(1-$F23*$F$3*$F$9,Donnees!$D$4)) -> 97.248442 | K23: =1/(1-POWER(1-$F23*$F$4*$F$8,Donnees!$D$4)) -> 18.144549 | L23: =1/(1-POWER(1-$F23*$F$4*$F$9,Donnees!$D$4)) -> 159.45905 | M23: =1/(1-POWER(1-$F23*$F$5*$F$8,Donnees!$D$4)) -> 35.807028 | N23: =1/(1-POWER(1-$F23*$F$5*$F$9,Donnees!$D$4)) -> 318.44232 | O23: =1/(1-POWER(1-$F23*$F$6*$F$8,Donnees!$D$4)) -> 106.4648 | P23: =1/(1-POWER(1-$F23*$F$6*$F$9,Donnees!$D$4)) -> 954.37626 | Q23: =1/(1-POWER(1-$F23*$F$7*$F$8,Donnees!$D$4)) -> 742.39825 | R23: =1/(1-POWER(1-$F23*$F$7*$F$9,Donnees!$D$4)) -> 6677.7832
A24: astronomes-en-herbe | B24: aeh-andromede-constellation | C24: Andromède | D24: Common | E24: =VLOOKUP(D24,$A$13:$F$16,5,FALSE)*_xlfn.XLOOKUP(Resultats!C24,Table1[name],Table1[cardRarityMultiplier]) -> 0.010416667 | F24: =E24/$E$118 -> 0.010483266 | G24: =1-POWER(1-E24,Donnees!$D$4) -> 0.18895034 | H24: =1/G24 -> 5.2923958 | I24: =1/(1-POWER(1-$F24*$F$3*$F$8,Donnees!$D$4)) -> 11.235257 | J24: =1/(1-POWER(1-$F24*$F$3*$F$9,Donnees!$D$4)) -> 97.248442 | K24: =1/(1-POWER(1-$F24*$F$4*$F$8,Donnees!$D$4)) -> 18.144549 | L24: =1/(1-POWER(1-$F24*$F$4*$F$9,Donnees!$D$4)) -> 159.45905 | M24: =1/(1-POWER(1-$F24*$F$5*$F$8,Donnees!$D$4)) -> 35.807028 | N24: =1/(1-POWER(1-$F24*$F$5*$F$9,Donnees!$D$4)) -> 318.44232 | O24: =1/(1-POWER(1-$F24*$F$6*$F$8,Donnees!$D$4)) -> 106.4648 | P24: =1/(1-POWER(1-$F24*$F$6*$F$9,Donnees!$D$4)) -> 954.37626 | Q24: =1/(1-POWER(1-$F24*$F$7*$F$8,Donnees!$D$4)) -> 742.39825 | R24: =1/(1-POWER(1-$F24*$F$7*$F$9,Donnees!$D$4)) -> 6677.7832
A25: astronomes-en-herbe | B25: aeh-arcturus | C25: Arcturus | D25: Common | E25: =VLOOKUP(D25,$A$13:$F$16,5,FALSE)*_xlfn.XLOOKUP(Resultats!C25,Table1[name],Table1[cardRarityMultiplier]) -> 0.010416667 | F25: =E25/$E$118 -> 0.010483266 | G25: =1-POWER(1-E25,Donnees!$D$4) -> 0.18895034 | H25: =1/G25 -> 5.2923958 | I25: =1/(1-POWER(1-$F25*$F$3*$F$8,Donnees!$D$4)) -> 11.235257 | J25: =1/(1-POWER(1-$F25*$F$3*$F$9,Donnees!$D$4)) -> 97.248442 | K25: =1/(1-POWER(1-$F25*$F$4*$F$8,Donnees!$D$4)) -> 18.144549 | L25: =1/(1-POWER(1-$F25*$F$4*$F$9,Donnees!$D$4)) -> 159.45905 | M25: =1/(1-POWER(1-$F25*$F$5*$F$8,Donnees!$D$4)) -> 35.807028 | N25: =1/(1-POWER(1-$F25*$F$5*$F$9,Donnees!$D$4)) -> 318.44232 | O25: =1/(1-POWER(1-$F25*$F$6*$F$8,Donnees!$D$4)) -> 106.4648 | P25: =1/(1-POWER(1-$F25*$F$6*$F$9,Donnees!$D$4)) -> 954.37626 | Q25: =1/(1-POWER(1-$F25*$F$7*$F$8,Donnees!$D$4)) -> 742.39825 | R25: =1/(1-POWER(1-$F25*$F$7*$F$9,Donnees!$D$4)) -> 6677.7832
A26: astronomes-en-herbe | B26: aeh-aurora-borealis | C26: Aurore boréale | D26: Epic | E26: =VLOOKUP(D26,$A$13:$F$16,5,FALSE)*_xlfn.XLOOKUP(Resultats!C26,Table1[name],Table1[cardRarityMultiplier]) -> 0.00625 | F26: =E26/$E$118 -> 0.0062899597 | G26: =1-POWER(1-E26,Donnees!$D$4) -> 0.1178492 | H26: =1/G26 -> 8.4854205 | I26: =1/(1-POWER(1-$F26*$F$3*$F$8,Donnees!$D$4)) -> 18.400493 | J26: =1/(1-POWER(1-$F26*$F$3*$F$9,Donnees!$D$4)) -> 161.76315 | K26: =1/(1-POWER(1-$F26*$F$4*$F$8,Donnees!$D$4)) -> 29.91922 | L26: =1/(1-POWER(1-$F26*$F$4*$F$9,Donnees!$D$4)) -> 265.44786 | M26: =1/(1-POWER(1-$F26*$F$5*$F$8,Donnees!$D$4)) -> 59.359201 | N26: =1/(1-POWER(1-$F26*$F$5*$F$9,Donnees!$D$4)) -> 530.42025 | O26: =1/(1-POWER(1-$F26*$F$6*$F$8,Donnees!$D$4)) -> 177.12384 | P26: =1/(1-POWER(1-$F26*$F$6*$F$9,Donnees!$D$4)) -> 1590.3103 | Q26: =1/(1-POWER(1-$F26*$F$7*$F$8,Donnees!$D$4)) -> 1237.0136 | R26: =1/(1-POWER(1-$F26*$F$7*$F$9,Donnees!$D$4)) -> 11129.322
A27: astronomes-en-herbe | B27: aeh-betelgeuse | C27: Bételgeuse | D27: Common | E27: =VLOOKUP(D27,$A$13:$F$16,5,FALSE)*_xlfn.XLOOKUP(Resultats!C27,Table1[name],Table1[cardRarityMultiplier]) -> 0.010416667 | F27: =E27/$E$118 -> 0.010483266 | G27: =1-POWER(1-E27,Donnees!$D$4) -> 0.18895034 | H27: =1/G27 -> 5.2923958 | I27: =1/(1-POWER(1-$F27*$F$3*$F$8,Donnees!$D$4)) -> 11.235257 | J27: =1/(1-POWER(1-$F27*$F$3*$F$9,Donnees!$D$4)) -> 97.248442 | K27: =1/(1-POWER(1-$F27*$F$4*$F$8,Donnees!$D$4)) -> 18.144549 | L27: =1/(1-POWER(1-$F27*$F$4*$F$9,Donnees!$D$4)) -> 159.45905 | M27: =1/(1-POWER(1-$F27*$F$5*$F$8,Donnees!$D$4)) -> 35.807028 | N27: =1/(1-POWER(1-$F27*$F$5*$F$9,Donnees!$D$4)) -> 318.44232 | O27: =1/(1-POWER(1-$F27*$F$6*$F$8,Donnees!$D$4)) -> 106.4648 | P27: =1/(1-POWER(1-$F27*$F$6*$F$9,Donnees!$D$4)) -> 954.37626 | Q27: =1/(1-POWER(1-$F27*$F$7*$F$8,Donnees!$D$4)) -> 742.39825 | R27: =1/(1-POWER(1-$F27*$F$7*$F$9,Donnees!$D$4)) -> 6677.7832
A28: astronomes-en-herbe | B28: aeh-capella | C28: Capella | D28: Common | E28: =VLOOKUP(D28,$A$13:$F$16,5,FALSE)*_xlfn.XLOOKUP(Resultats!C28,Table1[name],Table1[cardRarityMultiplier]) -> 0.010416667 | F28: =E28/$E$118 -> 0.010483266 | G28: =1-POWER(1-E28,Donnees!$D$4) -> 0.18895034 | H28: =1/G28 -> 5.2923958 | I28: =1/(1-POWER(1-$F28*$F$3*$F$8,Donnees!$D$4)) -> 11.235257 | J28: =1/(1-POWER(1-$F28*$F$3*$F$9,Donnees!$D$4)) -> 97.248442 | K28: =1/(1-POWER(1-$F28*$F$4*$F$8,Donnees!$D$4)) -> 18.144549 | L28: =1/(1-POWER(1-$F28*$F$4*$F$9,Donnees!$D$4)) -> 159.45905 | M28: =1/(1-POWER(1-$F28*$F$5*$F$8,Donnees!$D$4)) -> 35.807028 | N28: =1/(1-POWER(1-$F28*$F$5*$F$9,Donnees!$D$4)) -> 318.44232 | O28: =1/(1-POWER(1-$F28*$F$6*$F$8,Donnees!$D$4)) -> 106.4648 | P28: =1/(1-POWER(1-$F28*$F$6*$F$9,Donnees!$D$4)) -> 954.37626 | Q28: =1/(1-POWER(1-$F28*$F$7*$F$8,Donnees!$D$4)) -> 742.39825 | R28: =1/(1-POWER(1-$F28*$F$7*$F$9,Donnees!$D$4)) -> 6677.7832
A29: astronomes-en-herbe | B29: aeh-cassiopeia | C29: Cassiopée | D29: Common | E29: =VLOOKUP(D29,$A$13:$F$16,5,FALSE)*_xlfn.XLOOKUP(Resultats!C29,Table1[name],Table1[cardRarityMultiplier]) -> 0.010416667 | F29: =E29/$E$118 -> 0.010483266 | G29: =1-POWER(1-E29,Donnees!$D$4) -> 0.18895034 | H29: =1/G29 -> 5.2923958 | I29: =1/(1-POWER(1-$F29*$F$3*$F$8,Donnees!$D$4)) -> 11.235257 | J29: =1/(1-POWER(1-$F29*$F$3*$F$9,Donnees!$D$4)) -> 97.248442 | K29: =1/(1-POWER(1-$F29*$F$4*$F$8,Donnees!$D$4)) -> 18.144549 | L29: =1/(1-POWER(1-$F29*$F$4*$F$9,Donnees!$D$4)) -> 159.45905 | M29: =1/(1-POWER(1-$F29*$F$5*$F$8,Donnees!$D$4)) -> 35.807028 | N29: =1/(1-POWER(1-$F29*$F$5*$F$9,Donnees!$D$4)) -> 318.44232 | O29: =1/(1-POWER(1-$F29*$F$6*$F$8,Donnees!$D$4)) -> 106.4648 | P29: =1/(1-POWER(1-$F29*$F$6*$F$9,Donnees!$D$4)) -> 954.37626 | Q29: =1/(1-POWER(1-$F29*$F$7*$F$8,Donnees!$D$4)) -> 742.39825 | R29: =1/(1-POWER(1-$F29*$F$7*$F$9,Donnees!$D$4)) -> 6677.7832
A30: astronomes-en-herbe | B30: aeh-coathanger | C30: Amas du Cintre | D30: Uncommon | E30: =VLOOKUP(D30,$A$13:$F$16,5,FALSE)*_xlfn.XLOOKUP(Resultats!C30,Table1[name],Table1[cardRarityMultiplier]) -> 0.012 | F30: =E30/$E$118 -> 0.012076723 | G30: =1-POWER(1-E30,Donnees!$D$4) -> 0.2145132 | H30: =1/G30 -> 4.6617178 | I30: =1/(1-POWER(1-$F30*$F$3*$F$8,Donnees!$D$4)) -> 9.8177034 | J30: =1/(1-POWER(1-$F30*$F$3*$F$9,Donnees!$D$4)) -> 84.479968 | K30: =1/(1-POWER(1-$F30*$F$4*$F$8,Donnees!$D$4)) -> 15.814489 | L30: =1/(1-POWER(1-$F30*$F$4*$F$9,Donnees!$D$4)) -> 138.48214 | M30: =1/(1-POWER(1-$F30*$F$5*$F$8,Donnees!$D$4)) -> 31.145832 | N30: =1/(1-POWER(1-$F30*$F$5*$F$9,Donnees!$D$4)) -> 276.48837 | O30: =1/(1-POWER(1-$F30*$F$6*$F$8,Donnees!$D$4)) -> 92.480261 | P30: =1/(1-POWER(1-$F30*$F$6*$F$9,Donnees!$D$4)) -> 828.51432 | Q30: =1/(1-POWER(1-$F30*$F$7*$F$8,Donnees!$D$4)) -> 644.50563 | R30: =1/(1-POWER(1-$F30*$F$7*$F$9,Donnees!$D$4)) -> 5796.7495
A31: astronomes-en-herbe | B31: aeh-comet-neowise | C31: Comète C/2020 F3 NEOWISE | D31: Epic | E31: =VLOOKUP(D31,$A$13:$F$16,5,FALSE)*_xlfn.XLOOKUP(Resultats!C31,Table1[name],Table1[cardRarityMultiplier]) -> 0.00625 | F31: =E31/$E$118 -> 0.0062899597 | G31: =1-POWER(1-E31,Donnees!$D$4) -> 0.1178492 | H31: =1/G31 -> 8.4854205 | I31: =1/(1-POWER(1-$F31*$F$3*$F$8,Donnees!$D$4)) -> 18.400493 | J31: =1/(1-POWER(1-$F31*$F$3*$F$9,Donnees!$D$4)) -> 161.76315 | K31: =1/(1-POWER(1-$F31*$F$4*$F$8,Donnees!$D$4)) -> 29.91922 | L31: =1/(1-POWER(1-$F31*$F$4*$F$9,Donnees!$D$4)) -> 265.44786 | M31: =1/(1-POWER(1-$F31*$F$5*$F$8,Donnees!$D$4)) -> 59.359201 | N31: =1/(1-POWER(1-$F31*$F$5*$F$9,Donnees!$D$4)) -> 530.42025 | O31: =1/(1-POWER(1-$F31*$F$6*$F$8,Donnees!$D$4)) -> 177.12384 | P31: =1/(1-POWER(1-$F31*$F$6*$F$9,Donnees!$D$4)) -> 1590.3103 | Q31: =1/(1-POWER(1-$F31*$F$7*$F$8,Donnees!$D$4)) -> 1237.0136 | R31: =1/(1-POWER(1-$F31*$F$7*$F$9,Donnees!$D$4)) -> 11129.322
... A69: astronomes-en-herbe | B69: aeh-grande-ourse | C69: Grande Ourse | D69: Common | E69: =VLOOKUP(D69,$A$13:$F$16,5,FALSE)*_xlfn.XLOOKUP(Resultats!C69,Table1[name],Table1[cardRarityMultiplier]) -> 0.010416667 | F69: =E69/$E$118 -> 0.010483266 | G69: =1-POWER(1-E69,Donnees!$D$4) -> 0.18895034 | H69: =1/G69 -> 5.2923958 | I69: =1/(1-POWER(1-$F69*$F$3*$F$8,Donnees!$D$4)) -> 11.235257 | J69: =1/(1-POWER(1-$F69*$F$3*$F$9,Donnees!$D$4)) -> 97.248442 | K69: =1/(1-POWER(1-$F69*$F$4*$F$8,Donnees!$D$4)) -> 18.144549 | L69: =1/(1-POWER(1-$F69*$F$4*$F$9,Donnees!$D$4)) -> 159.45905 | M69: =1/(1-POWER(1-$F69*$F$5*$F$8,Donnees!$D$4)) -> 35.807028 | N69: =1/(1-POWER(1-$F69*$F$5*$F$9,Donnees!$D$4)) -> 318.44232 | O69: =1/(1-POWER(1-$F69*$F$6*$F$8,Donnees!$D$4)) -> 106.4648 | P69: =1/(1-POWER(1-$F69*$F$6*$F$9,Donnees!$D$4)) -> 954.37626 | Q69: =1/(1-POWER(1-$F69*$F$7*$F$8,Donnees!$D$4)) -> 742.39825 | R69: =1/(1-POWER(1-$F69*$F$7*$F$9,Donnees!$D$4)) -> 6677.7832
B70: ss-mercury | C70: Mercure | D70: Rare | E70: =VLOOKUP(D70,$A$13:$F$16,5,FALSE)*_xlfn.XLOOKUP(Resultats!C70,Table1[name],Table1[cardRarityMultiplier]) -> 0.0088235294 | F70: =E70/$E$118 -> 0.0088799432 | G70: =1-POWER(1-E70,Donnees!$D$4) -> 0.16243277 | H70: =1/G70 -> 6.1563932 | I70: =1/(1-POWER(1-$F70*$F$3*$F$8,Donnees!$D$4)) -> 13.175495 | J70: =1/(1-POWER(1-$F70*$F$3*$F$9,Donnees!$D$4)) -> 114.72114 | K70: =1/(1-POWER(1-$F70*$F$4*$F$8,Donnees!$D$4)) -> 21.333312 | L70: =1/(1-POWER(1-$F70*$F$4*$F$9,Donnees!$D$4)) -> 188.16433 | M70: =1/(1-POWER(1-$F70*$F$5*$F$8,Donnees!$D$4)) -> 42.185636 | N70: =1/(1-POWER(1-$F70*$F$5*$F$9,Donnees!$D$4)) -> 375.853 | O70: =1/(1-POWER(1-$F70*$F$6*$F$8,Donnees!$D$4)) -> 125.60159 | P70: =1/(1-POWER(1-$F70*$F$6*$F$9,Donnees!$D$4)) -> 1126.6084 | Q70: =1/(1-POWER(1-$F70*$F$7*$F$8,Donnees!$D$4)) -> 876.35658 | R70: =1/(1-POWER(1-$F70*$F$7*$F$9,Donnees!$D$4)) -> 7883.4083
B71: ss-venus | C71: Vénus | D71: Rare | E71: =VLOOKUP(D71,$A$13:$F$16,5,FALSE)*_xlfn.XLOOKUP(Resultats!C71,Table1[name],Table1[cardRarityMultiplier]) -> 0.0088235294 | F71: =E71/$E$118 -> 0.0088799432 | G71: =1-POWER(1-E71,Donnees!$D$4) -> 0.16243277 | H71: =1/G71 -> 6.1563932 | I71: =1/(1-POWER(1-$F71*$F$3*$F$8,Donnees!$D$4)) -> 13.175495 | J71: =1/(1-POWER(1-$F71*$F$3*$F$9,Donnees!$D$4)) -> 114.72114 | K71: =1/(1-POWER(1-$F71*$F$4*$F$8,Donnees!$D$4)) -> 21.333312 | L71: =1/(1-POWER(1-$F71*$F$4*$F$9,Donnees!$D$4)) -> 188.16433 | M71: =1/(1-POWER(1-$F71*$F$5*$F$8,Donnees!$D$4)) -> 42.185636 | N71: =1/(1-POWER(1-$F71*$F$5*$F$9,Donnees!$D$4)) -> 375.853 | O71: =1/(1-POWER(1-$F71*$F$6*$F$8,Donnees!$D$4)) -> 125.60159 | P71: =1/(1-POWER(1-$F71*$F$6*$F$9,Donnees!$D$4)) -> 1126.6084 | Q71: =1/(1-POWER(1-$F71*$F$7*$F$8,Donnees!$D$4)) -> 876.35658 | R71: =1/(1-POWER(1-$F71*$F$7*$F$9,Donnees!$D$4)) -> 7883.4083
B72: ss-earth | C72: Terre | D72: Epic | E72: =VLOOKUP(D72,$A$13:$F$16,5,FALSE)*_xlfn.XLOOKUP(Resultats!C72,Table1[name],Table1[cardRarityMultiplier]) -> 0.00625 | F72: =E72/$E$118 -> 0.0062899597 | G72: =1-POWER(1-E72,Donnees!$D$4) -> 0.1178492 | H72: =1/G72 -> 8.4854205 | I72: =1/(1-POWER(1-$F72*$F$3*$F$8,Donnees!$D$4)) -> 18.400493 | J72: =1/(1-POWER(1-$F72*$F$3*$F$9,Donnees!$D$4)) -> 161.76315 | K72: =1/(1-POWER(1-$F72*$F$4*$F$8,Donnees!$D$4)) -> 29.91922 | L72: =1/(1-POWER(1-$F72*$F$4*$F$9,Donnees!$D$4)) -> 265.44786 | M72: =1/(1-POWER(1-$F72*$F$5*$F$8,Donnees!$D$4)) -> 59.359201 | N72: =1/(1-POWER(1-$F72*$F$5*$F$9,Donnees!$D$4)) -> 530.42025 | O72: =1/(1-POWER(1-$F72*$F$6*$F$8,Donnees!$D$4)) -> 177.12384 | P72: =1/(1-POWER(1-$F72*$F$6*$F$9,Donnees!$D$4)) -> 1590.3103 | Q72: =1/(1-POWER(1-$F72*$F$7*$F$8,Donnees!$D$4)) -> 1237.0136 | R72: =1/(1-POWER(1-$F72*$F$7*$F$9,Donnees!$D$4)) -> 11129.322
B73: ss-mars | C73: Mars | D73: Epic | E73: =VLOOKUP(D73,$A$13:$F$16,5,FALSE)*_xlfn.XLOOKUP(Resultats!C73,Table1[name],Table1[cardRarityMultiplier]) -> 0.00625 | F73: =E73/$E$118 -> 0.0062899597 | G73: =1-POWER(1-E73,Donnees!$D$4) -> 0.1178492 | H73: =1/G73 -> 8.4854205 | I73: =1/(1-POWER(1-$F73*$F$3*$F$8,Donnees!$D$4)) -> 18.400493 | J73: =1/(1-POWER(1-$F73*$F$3*$F$9,Donnees!$D$4)) -> 161.76315 | K73: =1/(1-POWER(1-$F73*$F$4*$F$8,Donnees!$D$4)) -> 29.91922 | L73: =1/(1-POWER(1-$F73*$F$4*$F$9,Donnees!$D$4)) -> 265.44786 | M73: =1/(1-POWER(1-$F73*$F$5*$F$8,Donnees!$D$4)) -> 59.359201 | N73: =1/(1-POWER(1-$F73*$F$5*$F$9,Donnees!$D$4)) -> 530.42025 | O73: =1/(1-POWER(1-$F73*$F$6*$F$8,Donnees!$D$4)) -> 177.12384 | P73: =1/(1-POWER(1-$F73*$F$6*$F$9,Donnees!$D$4)) -> 1590.3103 | Q73: =1/(1-POWER(1-$F73*$F$7*$F$8,Donnees!$D$4)) -> 1237.0136 | R73: =1/(1-POWER(1-$F73*$F$7*$F$9,Donnees!$D$4)) -> 11129.322
B74: ss-jupiter | C74: Jupiter | D74: Epic | E74: =VLOOKUP(D74,$A$13:$F$16,5,FALSE)*_xlfn.XLOOKUP(Resultats!C74,Table1[name],Table1[cardRarityMultiplier]) -> 0.00625 | F74: =E74/$E$118 -> 0.0062899597 | G74: =1-POWER(1-E74,Donnees!$D$4) -> 0.1178492 | H74: =1/G74 -> 8.4854205 | I74: =1/(1-POWER(1-$F74*$F$3*$F$8,Donnees!$D$4)) -> 18.400493 | J74: =1/(1-POWER(1-$F74*$F$3*$F$9,Donnees!$D$4)) -> 161.76315 | K74: =1/(1-POWER(1-$F74*$F$4*$F$8,Donnees!$D$4)) -> 29.91922 | L74: =1/(1-POWER(1-$F74*$F$4*$F$9,Donnees!$D$4)) -> 265.44786 | M74: =1/(1-POWER(1-$F74*$F$5*$F$8,Donnees!$D$4)) -> 59.359201 | N74: =1/(1-POWER(1-$F74*$F$5*$F$9,Donnees!$D$4)) -> 530.42025 | O74: =1/(1-POWER(1-$F74*$F$6*$F$8,Donnees!$D$4)) -> 177.12384 | P74: =1/(1-POWER(1-$F74*$F$6*$F$9,Donnees!$D$4)) -> 1590.3103 | Q74: =1/(1-POWER(1-$F74*$F$7*$F$8,Donnees!$D$4)) -> 1237.0136 | R74: =1/(1-POWER(1-$F74*$F$7*$F$9,Donnees!$D$4)) -> 11129.322
B75: ss-saturn | C75: Saturne | D75: Epic | E75: =VLOOKUP(D75,$A$13:$F$16,5,FALSE)*_xlfn.XLOOKUP(Resultats!C75,Table1[name],Table1[cardRarityMultiplier]) -> 0.00625 | F75: =E75/$E$118 -> 0.0062899597 | G75: =1-POWER(1-E75,Donnees!$D$4) -> 0.1178492 | H75: =1/G75 -> 8.4854205 | I75: =1/(1-POWER(1-$F75*$F$3*$F$8,Donnees!$D$4)) -> 18.400493 | J75: =1/(1-POWER(1-$F75*$F$3*$F$9,Donnees!$D$4)) -> 161.76315 | K75: =1/(1-POWER(1-$F75*$F$4*$F$8,Donnees!$D$4)) -> 29.91922 | L75: =1/(1-POWER(1-$F75*$F$4*$F$9,Donnees!$D$4)) -> 265.44786 | M75: =1/(1-POWER(1-$F75*$F$5*$F$8,Donnees!$D$4)) -> 59.359201 | N75: =1/(1-POWER(1-$F75*$F$5*$F$9,Donnees!$D$4)) -> 530.42025 | O75: =1/(1-POWER(1-$F75*$F$6*$F$8,Donnees!$D$4)) -> 177.12384 | P75: =1/(1-POWER(1-$F75*$F$6*$F$9,Donnees!$D$4)) -> 1590.3103 | Q75: =1/(1-POWER(1-$F75*$F$7*$F$8,Donnees!$D$4)) -> 1237.0136 | R75: =1/(1-POWER(1-$F75*$F$7*$F$9,Donnees!$D$4)) -> 11129.322
B76: ss-uranus | C76: Uranus | D76: Rare | E76: =VLOOKUP(D76,$A$13:$F$16,5,FALSE)*_xlfn.XLOOKUP(Resultats!C76,Table1[name],Table1[cardRarityMultiplier]) -> 0.0088235294 | F76: =E76/$E$118 -> 0.0088799432 | G76: =1-POWER(1-E76,Donnees!$D$4) -> 0.16243277 | H76: =1/G76 -> 6.1563932 | I76: =1/(1-POWER(1-$F76*$F$3*$F$8,Donnees!$D$4)) -> 13.175495 | J76: =1/(1-POWER(1-$F76*$F$3*$F$9,Donnees!$D$4)) -> 114.72114 | K76: =1/(1-POWER(1-$F76*$F$4*$F$8,Donnees!$D$4)) -> 21.333312 | L76: =1/(1-POWER(1-$F76*$F$4*$F$9,Donnees!$D$4)) -> 188.16433 | M76: =1/(1-POWER(1-$F76*$F$5*$F$8,Donnees!$D$4)) -> 42.185636 | N76: =1/(1-POWER(1-$F76*$F$5*$F$9,Donnees!$D$4)) -> 375.853 | O76: =1/(1-POWER(1-$F76*$F$6*$F$8,Donnees!$D$4)) -> 125.60159 | P76: =1/(1-POWER(1-$F76*$F$6*$F$9,Donnees!$D$4)) -> 1126.6084 | Q76: =1/(1-POWER(1-$F76*$F$7*$F$8,Donnees!$D$4)) -> 876.35658 | R76: =1/(1-POWER(1-$F76*$F$7*$F$9,Donnees!$D$4)) -> 7883.4083
B77: ss-neptune | C77: Neptune | D77: Rare | E77: =VLOOKUP(D77,$A$13:$F$16,5,FALSE)*_xlfn.XLOOKUP(Resultats!C77,Table1[name],Table1[cardRarityMultiplier]) -> 0.0088235294 | F77: =E77/$E$118 -> 0.0088799432 | G77: =1-POWER(1-E77,Donnees!$D$4) -> 0.16243277 | H77: =1/G77 -> 6.1563932 | I77: =1/(1-POWER(1-$F77*$F$3*$F$8,Donnees!$D$4)) -> 13.175495 | J77: =1/(1-POWER(1-$F77*$F$3*$F$9,Donnees!$D$4)) -> 114.72114 | K77: =1/(1-POWER(1-$F77*$F$4*$F$8,Donnees!$D$4)) -> 21.333312 | L77: =1/(1-POWER(1-$F77*$F$4*$F$9,Donnees!$D$4)) -> 188.16433 | M77: =1/(1-POWER(1-$F77*$F$5*$F$8,Donnees!$D$4)) -> 42.185636 | N77: =1/(1-POWER(1-$F77*$F$5*$F$9,Donnees!$D$4)) -> 375.853 | O77: =1/(1-POWER(1-$F77*$F$6*$F$8,Donnees!$D$4)) -> 125.60159 | P77: =1/(1-POWER(1-$F77*$F$6*$F$9,Donnees!$D$4)) -> 1126.6084 | Q77: =1/(1-POWER(1-$F77*$F$7*$F$8,Donnees!$D$4)) -> 876.35658 | R77: =1/(1-POWER(1-$F77*$F$7*$F$9,Donnees!$D$4)) -> 7883.4083
B78: ss-ceres | C78: Cérès | D78: Common | E78: =VLOOKUP(D78,$A$13:$F$16,5,FALSE)*_xlfn.XLOOKUP(Resultats!C78,Table1[name],Table1[cardRarityMultiplier]) -> 0.010416667 | F78: =E78/$E$118 -> 0.010483266 | G78: =1-POWER(1-E78,Donnees!$D$4) -> 0.18895034 | H78: =1/G78 -> 5.2923958 | I78: =1/(1-POWER(1-$F78*$F$3*$F$8,Donnees!$D$4)) -> 11.235257 | J78: =1/(1-POWER(1-$F78*$F$3*$F$9,Donnees!$D$4)) -> 97.248442 | K78: =1/(1-POWER(1-$F78*$F$4*$F$8,Donnees!$D$4)) -> 18.144549 | L78: =1/(1-POWER(1-$F78*$F$4*$F$9,Donnees!$D$4)) -> 159.45905 | M78: =1/(1-POWER(1-$F78*$F$5*$F$8,Donnees!$D$4)) -> 35.807028 | N78: =1/(1-POWER(1-$F78*$F$5*$F$9,Donnees!$D$4)) -> 318.44232 | O78: =1/(1-POWER(1-$F78*$F$6*$F$8,Donnees!$D$4)) -> 106.4648 | P78: =1/(1-POWER(1-$F78*$F$6*$F$9,Donnees!$D$4)) -> 954.37626 | Q78: =1/(1-POWER(1-$F78*$F$7*$F$8,Donnees!$D$4)) -> 742.39825 | R78: =1/(1-POWER(1-$F78*$F$7*$F$9,Donnees!$D$4)) -> 6677.7832
B79: ss-pluto | C79: Pluton | D79: Uncommon | E79: =VLOOKUP(D79,$A$13:$F$16,5,FALSE)*_xlfn.XLOOKUP(Resultats!C79,Table1[name],Table1[cardRarityMultiplier]) -> 0.012 | F79: =E79/$E$118 -> 0.012076723 | G79: =1-POWER(1-E79,Donnees!$D$4) -> 0.2145132 | H79: =1/G79 -> 4.6617178 | I79: =1/(1-POWER(1-$F79*$F$3*$F$8,Donnees!$D$4)) -> 9.8177034 | J79: =1/(1-POWER(1-$F79*$F$3*$F$9,Donnees!$D$4)) -> 84.479968 | K79: =1/(1-POWER(1-$F79*$F$4*$F$8,Donnees!$D$4)) -> 15.814489 | L79: =1/(1-POWER(1-$F79*$F$4*$F$9,Donnees!$D$4)) -> 138.48214 | M79: =1/(1-POWER(1-$F79*$F$5*$F$8,Donnees!$D$4)) -> 31.145832 | N79: =1/(1-POWER(1-$F79*$F$5*$F$9,Donnees!$D$4)) -> 276.48837 | O79: =1/(1-POWER(1-$F79*$F$6*$F$8,Donnees!$D$4)) -> 92.480261 | P79: =1/(1-POWER(1-$F79*$F$6*$F$9,Donnees!$D$4)) -> 828.51432 | Q79: =1/(1-POWER(1-$F79*$F$7*$F$8,Donnees!$D$4)) -> 644.50563 | R79: =1/(1-POWER(1-$F79*$F$7*$F$9,Donnees!$D$4)) -> 5796.7495
...
